2024-11-28 18:45:49,516 - app - ERROR - Exception on /agencia [POST]
Traceback (most recent call last):
  File "D:\MVP_FullStack_Backend\env\Lib\site-packages\sqlalchemy\engine\base.py", line 1967, in _exec_single_context
    self.dialect.do_execute(
    ~~~~~~~~~~~~~~~~~~~~~~~^
        cursor, str_statement, effective_parameters, context
        ^^^^^^^^^^^^^^^^^^^^^^^^^^^^^^^^^^^^^^^^^^^^^^^^^^^^
    )
    ^
  File "D:\MVP_FullStack_Backend\env\Lib\site-packages\sqlalchemy\engine\default.py", line 941, in do_execute
    cursor.execute(statement, parameters)
    ~~~~~~~~~~~~~~^^^^^^^^^^^^^^^^^^^^^^^
sqlite3.IntegrityError: UNIQUE constraint failed: agencia.idAgencia, agencia.idBanco

The above exception was the direct cause of the following exception:

Traceback (most recent call last):
  File "D:\MVP_FullStack_Backend\app.py", line 292, in add_agencia
    session.commit()
    ~~~~~~~~~~~~~~^^
  File "D:\MVP_FullStack_Backend\env\Lib\site-packages\sqlalchemy\orm\session.py", line 2028, in commit
    trans.commit(_to_root=True)
    ~~~~~~~~~~~~^^^^^^^^^^^^^^^
  File "<string>", line 2, in commit
  File "D:\MVP_FullStack_Backend\env\Lib\site-packages\sqlalchemy\orm\state_changes.py", line 139, in _go
    ret_value = fn(self, *arg, **kw)
  File "D:\MVP_FullStack_Backend\env\Lib\site-packages\sqlalchemy\orm\session.py", line 1313, in commit
    self._prepare_impl()
    ~~~~~~~~~~~~~~~~~~^^
  File "<string>", line 2, in _prepare_impl
  File "D:\MVP_FullStack_Backend\env\Lib\site-packages\sqlalchemy\orm\state_changes.py", line 139, in _go
    ret_value = fn(self, *arg, **kw)
  File "D:\MVP_FullStack_Backend\env\Lib\site-packages\sqlalchemy\orm\session.py", line 1288, in _prepare_impl
    self.session.flush()
    ~~~~~~~~~~~~~~~~~~^^
  File "D:\MVP_FullStack_Backend\env\Lib\site-packages\sqlalchemy\orm\session.py", line 4352, in flush
    self._flush(objects)
    ~~~~~~~~~~~^^^^^^^^^
  File "D:\MVP_FullStack_Backend\env\Lib\site-packages\sqlalchemy\orm\session.py", line 4487, in _flush
    with util.safe_reraise():
         ~~~~~~~~~~~~~~~~~^^
  File "D:\MVP_FullStack_Backend\env\Lib\site-packages\sqlalchemy\util\langhelpers.py", line 146, in __exit__
    raise exc_value.with_traceback(exc_tb)
  File "D:\MVP_FullStack_Backend\env\Lib\site-packages\sqlalchemy\orm\session.py", line 4448, in _flush
    flush_context.execute()
    ~~~~~~~~~~~~~~~~~~~~~^^
  File "D:\MVP_FullStack_Backend\env\Lib\site-packages\sqlalchemy\orm\unitofwork.py", line 466, in execute
    rec.execute(self)
    ~~~~~~~~~~~^^^^^^
  File "D:\MVP_FullStack_Backend\env\Lib\site-packages\sqlalchemy\orm\unitofwork.py", line 642, in execute
    util.preloaded.orm_persistence.save_obj(
    ~~~~~~~~~~~~~~~~~~~~~~~~~~~~~~~~~~~~~~~^
        self.mapper,
        ^^^^^^^^^^^^
        uow.states_for_mapper_hierarchy(self.mapper, False, False),
        ^^^^^^^^^^^^^^^^^^^^^^^^^^^^^^^^^^^^^^^^^^^^^^^^^^^^^^^^^^^
        uow,
        ^^^^
    )
    ^
  File "D:\MVP_FullStack_Backend\env\Lib\site-packages\sqlalchemy\orm\persistence.py", line 93, in save_obj
    _emit_insert_statements(
    ~~~~~~~~~~~~~~~~~~~~~~~^
        base_mapper,
        ^^^^^^^^^^^^
    ...<3 lines>...
        insert,
        ^^^^^^^
    )
    ^
  File "D:\MVP_FullStack_Backend\env\Lib\site-packages\sqlalchemy\orm\persistence.py", line 1048, in _emit_insert_statements
    result = connection.execute(
        statement, multiparams, execution_options=execution_options
    )
  File "D:\MVP_FullStack_Backend\env\Lib\site-packages\sqlalchemy\engine\base.py", line 1418, in execute
    return meth(
        self,
        distilled_parameters,
        execution_options or NO_OPTIONS,
    )
  File "D:\MVP_FullStack_Backend\env\Lib\site-packages\sqlalchemy\sql\elements.py", line 515, in _execute_on_connection
    return connection._execute_clauseelement(
           ~~~~~~~~~~~~~~~~~~~~~~~~~~~~~~~~~^
        self, distilled_params, execution_options
        ^^^^^^^^^^^^^^^^^^^^^^^^^^^^^^^^^^^^^^^^^
    )
    ^
  File "D:\MVP_FullStack_Backend\env\Lib\site-packages\sqlalchemy\engine\base.py", line 1640, in _execute_clauseelement
    ret = self._execute_context(
        dialect,
    ...<8 lines>...
        cache_hit=cache_hit,
    )
  File "D:\MVP_FullStack_Backend\env\Lib\site-packages\sqlalchemy\engine\base.py", line 1846, in _execute_context
    return self._exec_single_context(
           ~~~~~~~~~~~~~~~~~~~~~~~~~^
        dialect, context, statement, parameters
        ^^^^^^^^^^^^^^^^^^^^^^^^^^^^^^^^^^^^^^^
    )
    ^
  File "D:\MVP_FullStack_Backend\env\Lib\site-packages\sqlalchemy\engine\base.py", line 1986, in _exec_single_context
    self._handle_dbapi_exception(
    ~~~~~~~~~~~~~~~~~~~~~~~~~~~~^
        e, str_statement, effective_parameters, cursor, context
        ^^^^^^^^^^^^^^^^^^^^^^^^^^^^^^^^^^^^^^^^^^^^^^^^^^^^^^^
    )
    ^
  File "D:\MVP_FullStack_Backend\env\Lib\site-packages\sqlalchemy\engine\base.py", line 2355, in _handle_dbapi_exception
    raise sqlalchemy_exception.with_traceback(exc_info[2]) from e
  File "D:\MVP_FullStack_Backend\env\Lib\site-packages\sqlalchemy\engine\base.py", line 1967, in _exec_single_context
    self.dialect.do_execute(
    ~~~~~~~~~~~~~~~~~~~~~~~^
        cursor, str_statement, effective_parameters, context
        ^^^^^^^^^^^^^^^^^^^^^^^^^^^^^^^^^^^^^^^^^^^^^^^^^^^^
    )
    ^
  File "D:\MVP_FullStack_Backend\env\Lib\site-packages\sqlalchemy\engine\default.py", line 941, in do_execute
    cursor.execute(statement, parameters)
    ~~~~~~~~~~~~~~^^^^^^^^^^^^^^^^^^^^^^^
sqlalchemy.exc.IntegrityError: (sqlite3.IntegrityError) UNIQUE constraint failed: agencia.idAgencia, agencia.idBanco
[SQL: INSERT INTO agencia ("idBanco", "idAgencia", descricao) VALUES (?, ?, ?)]
[parameters: (1, 123456, 'FARTURA')]
(Background on this error at: https://sqlalche.me/e/20/gkpj)

During handling of the above exception, another exception occurred:

Traceback (most recent call last):
  File "D:\MVP_FullStack_Backend\env\Lib\site-packages\flask\app.py", line 1473, in wsgi_app
    response = self.full_dispatch_request()
  File "D:\MVP_FullStack_Backend\env\Lib\site-packages\flask\app.py", line 882, in full_dispatch_request
    rv = self.handle_user_exception(e)
  File "D:\MVP_FullStack_Backend\env\Lib\site-packages\flask_cors\extension.py", line 194, in wrapped_function
    return cors_after_request(app.make_response(f(*args, **kwargs)))
                                                ~^^^^^^^^^^^^^^^^^
  File "D:\MVP_FullStack_Backend\env\Lib\site-packages\flask\app.py", line 880, in full_dispatch_request
    rv = self.dispatch_request()
  File "D:\MVP_FullStack_Backend\env\Lib\site-packages\flask\app.py", line 865, in dispatch_request
    return self.ensure_sync(self.view_functions[rule.endpoint])(**view_args)  # type: ignore[no-any-return]
           ~~~~~~~~~~~~~~~~~~~~~~~~~~~~~~~~~~~~~~~~~~~~~~~~~~~~^^^^^^^^^^^^^
  File "D:\MVP_FullStack_Backend\env\Lib\site-packages\flask_openapi3\scaffold.py", line 117, in view_func
    response = func(**func_kwargs)
  File "D:\MVP_FullStack_Backend\app.py", line 302, in add_agencia
    logger.warning(f"Erro ao adicionar nova agência bancária '{agencia.idBanco}', '{agencia.idAgencia}', {error_msg}")
                                                                                                          ^^^^^^^^^
UnboundLocalError: cannot access local variable 'error_msg' where it is not associated with a value
2024-11-28 18:46:17,042 - app - ERROR - Exception on /agencia [POST]
Traceback (most recent call last):
  File "D:\MVP_FullStack_Backend\env\Lib\site-packages\sqlalchemy\engine\base.py", line 1967, in _exec_single_context
    self.dialect.do_execute(
    ~~~~~~~~~~~~~~~~~~~~~~~^
        cursor, str_statement, effective_parameters, context
        ^^^^^^^^^^^^^^^^^^^^^^^^^^^^^^^^^^^^^^^^^^^^^^^^^^^^
    )
    ^
  File "D:\MVP_FullStack_Backend\env\Lib\site-packages\sqlalchemy\engine\default.py", line 941, in do_execute
    cursor.execute(statement, parameters)
    ~~~~~~~~~~~~~~^^^^^^^^^^^^^^^^^^^^^^^
sqlite3.IntegrityError: UNIQUE constraint failed: agencia.idAgencia, agencia.idBanco

The above exception was the direct cause of the following exception:

Traceback (most recent call last):
  File "D:\MVP_FullStack_Backend\app.py", line 292, in add_agencia
    session.commit()
    ~~~~~~~~~~~~~~^^
  File "D:\MVP_FullStack_Backend\env\Lib\site-packages\sqlalchemy\orm\session.py", line 2028, in commit
    trans.commit(_to_root=True)
    ~~~~~~~~~~~~^^^^^^^^^^^^^^^
  File "<string>", line 2, in commit
  File "D:\MVP_FullStack_Backend\env\Lib\site-packages\sqlalchemy\orm\state_changes.py", line 139, in _go
    ret_value = fn(self, *arg, **kw)
  File "D:\MVP_FullStack_Backend\env\Lib\site-packages\sqlalchemy\orm\session.py", line 1313, in commit
    self._prepare_impl()
    ~~~~~~~~~~~~~~~~~~^^
  File "<string>", line 2, in _prepare_impl
  File "D:\MVP_FullStack_Backend\env\Lib\site-packages\sqlalchemy\orm\state_changes.py", line 139, in _go
    ret_value = fn(self, *arg, **kw)
  File "D:\MVP_FullStack_Backend\env\Lib\site-packages\sqlalchemy\orm\session.py", line 1288, in _prepare_impl
    self.session.flush()
    ~~~~~~~~~~~~~~~~~~^^
  File "D:\MVP_FullStack_Backend\env\Lib\site-packages\sqlalchemy\orm\session.py", line 4352, in flush
    self._flush(objects)
    ~~~~~~~~~~~^^^^^^^^^
  File "D:\MVP_FullStack_Backend\env\Lib\site-packages\sqlalchemy\orm\session.py", line 4487, in _flush
    with util.safe_reraise():
         ~~~~~~~~~~~~~~~~~^^
  File "D:\MVP_FullStack_Backend\env\Lib\site-packages\sqlalchemy\util\langhelpers.py", line 146, in __exit__
    raise exc_value.with_traceback(exc_tb)
  File "D:\MVP_FullStack_Backend\env\Lib\site-packages\sqlalchemy\orm\session.py", line 4448, in _flush
    flush_context.execute()
    ~~~~~~~~~~~~~~~~~~~~~^^
  File "D:\MVP_FullStack_Backend\env\Lib\site-packages\sqlalchemy\orm\unitofwork.py", line 466, in execute
    rec.execute(self)
    ~~~~~~~~~~~^^^^^^
  File "D:\MVP_FullStack_Backend\env\Lib\site-packages\sqlalchemy\orm\unitofwork.py", line 642, in execute
    util.preloaded.orm_persistence.save_obj(
    ~~~~~~~~~~~~~~~~~~~~~~~~~~~~~~~~~~~~~~~^
        self.mapper,
        ^^^^^^^^^^^^
        uow.states_for_mapper_hierarchy(self.mapper, False, False),
        ^^^^^^^^^^^^^^^^^^^^^^^^^^^^^^^^^^^^^^^^^^^^^^^^^^^^^^^^^^^
        uow,
        ^^^^
    )
    ^
  File "D:\MVP_FullStack_Backend\env\Lib\site-packages\sqlalchemy\orm\persistence.py", line 93, in save_obj
    _emit_insert_statements(
    ~~~~~~~~~~~~~~~~~~~~~~~^
        base_mapper,
        ^^^^^^^^^^^^
    ...<3 lines>...
        insert,
        ^^^^^^^
    )
    ^
  File "D:\MVP_FullStack_Backend\env\Lib\site-packages\sqlalchemy\orm\persistence.py", line 1048, in _emit_insert_statements
    result = connection.execute(
        statement, multiparams, execution_options=execution_options
    )
  File "D:\MVP_FullStack_Backend\env\Lib\site-packages\sqlalchemy\engine\base.py", line 1418, in execute
    return meth(
        self,
        distilled_parameters,
        execution_options or NO_OPTIONS,
    )
  File "D:\MVP_FullStack_Backend\env\Lib\site-packages\sqlalchemy\sql\elements.py", line 515, in _execute_on_connection
    return connection._execute_clauseelement(
           ~~~~~~~~~~~~~~~~~~~~~~~~~~~~~~~~~^
        self, distilled_params, execution_options
        ^^^^^^^^^^^^^^^^^^^^^^^^^^^^^^^^^^^^^^^^^
    )
    ^
  File "D:\MVP_FullStack_Backend\env\Lib\site-packages\sqlalchemy\engine\base.py", line 1640, in _execute_clauseelement
    ret = self._execute_context(
        dialect,
    ...<8 lines>...
        cache_hit=cache_hit,
    )
  File "D:\MVP_FullStack_Backend\env\Lib\site-packages\sqlalchemy\engine\base.py", line 1846, in _execute_context
    return self._exec_single_context(
           ~~~~~~~~~~~~~~~~~~~~~~~~~^
        dialect, context, statement, parameters
        ^^^^^^^^^^^^^^^^^^^^^^^^^^^^^^^^^^^^^^^
    )
    ^
  File "D:\MVP_FullStack_Backend\env\Lib\site-packages\sqlalchemy\engine\base.py", line 1986, in _exec_single_context
    self._handle_dbapi_exception(
    ~~~~~~~~~~~~~~~~~~~~~~~~~~~~^
        e, str_statement, effective_parameters, cursor, context
        ^^^^^^^^^^^^^^^^^^^^^^^^^^^^^^^^^^^^^^^^^^^^^^^^^^^^^^^
    )
    ^
  File "D:\MVP_FullStack_Backend\env\Lib\site-packages\sqlalchemy\engine\base.py", line 2355, in _handle_dbapi_exception
    raise sqlalchemy_exception.with_traceback(exc_info[2]) from e
  File "D:\MVP_FullStack_Backend\env\Lib\site-packages\sqlalchemy\engine\base.py", line 1967, in _exec_single_context
    self.dialect.do_execute(
    ~~~~~~~~~~~~~~~~~~~~~~~^
        cursor, str_statement, effective_parameters, context
        ^^^^^^^^^^^^^^^^^^^^^^^^^^^^^^^^^^^^^^^^^^^^^^^^^^^^
    )
    ^
  File "D:\MVP_FullStack_Backend\env\Lib\site-packages\sqlalchemy\engine\default.py", line 941, in do_execute
    cursor.execute(statement, parameters)
    ~~~~~~~~~~~~~~^^^^^^^^^^^^^^^^^^^^^^^
sqlalchemy.exc.IntegrityError: (sqlite3.IntegrityError) UNIQUE constraint failed: agencia.idAgencia, agencia.idBanco
[SQL: INSERT INTO agencia ("idBanco", "idAgencia", descricao) VALUES (?, ?, ?)]
[parameters: (1, 123456, 'FARTURA')]
(Background on this error at: https://sqlalche.me/e/20/gkpj)

During handling of the above exception, another exception occurred:

Traceback (most recent call last):
  File "D:\MVP_FullStack_Backend\env\Lib\site-packages\flask\app.py", line 1473, in wsgi_app
    response = self.full_dispatch_request()
  File "D:\MVP_FullStack_Backend\env\Lib\site-packages\flask\app.py", line 882, in full_dispatch_request
    rv = self.handle_user_exception(e)
  File "D:\MVP_FullStack_Backend\env\Lib\site-packages\flask_cors\extension.py", line 194, in wrapped_function
    return cors_after_request(app.make_response(f(*args, **kwargs)))
                                                ~^^^^^^^^^^^^^^^^^
  File "D:\MVP_FullStack_Backend\env\Lib\site-packages\flask\app.py", line 880, in full_dispatch_request
    rv = self.dispatch_request()
  File "D:\MVP_FullStack_Backend\env\Lib\site-packages\flask\app.py", line 865, in dispatch_request
    return self.ensure_sync(self.view_functions[rule.endpoint])(**view_args)  # type: ignore[no-any-return]
           ~~~~~~~~~~~~~~~~~~~~~~~~~~~~~~~~~~~~~~~~~~~~~~~~~~~~^^^^^^^^^^^^^
  File "D:\MVP_FullStack_Backend\env\Lib\site-packages\flask_openapi3\scaffold.py", line 117, in view_func
    response = func(**func_kwargs)
  File "D:\MVP_FullStack_Backend\app.py", line 302, in add_agencia
    logger.warning(f"Erro ao adicionar nova agência bancária '{agencia.idBanco}', '{agencia.idAgencia}', {error_msg}")
                                                                                                          ^^^^^^^^^
UnboundLocalError: cannot access local variable 'error_msg' where it is not associated with a value
2024-11-29 11:33:06,318 - app - ERROR - Exception on /banco [POST]
Traceback (most recent call last):
  File "D:\MVP_FullStack_Backend\env\Lib\site-packages\sqlalchemy\engine\base.py", line 1967, in _exec_single_context
    self.dialect.do_execute(
    ~~~~~~~~~~~~~~~~~~~~~~~^
        cursor, str_statement, effective_parameters, context
        ^^^^^^^^^^^^^^^^^^^^^^^^^^^^^^^^^^^^^^^^^^^^^^^^^^^^
    )
    ^
  File "D:\MVP_FullStack_Backend\env\Lib\site-packages\sqlalchemy\engine\default.py", line 941, in do_execute
    cursor.execute(statement, parameters)
    ~~~~~~~~~~~~~~^^^^^^^^^^^^^^^^^^^^^^^
sqlite3.IntegrityError: UNIQUE constraint failed: banco.idBanco

The above exception was the direct cause of the following exception:

Traceback (most recent call last):
  File "D:\MVP_FullStack_Backend\app.py", line 246, in add_banco
    session.commit()
    ~~~~~~~~~~~~~~^^
  File "D:\MVP_FullStack_Backend\env\Lib\site-packages\sqlalchemy\orm\session.py", line 2028, in commit
    trans.commit(_to_root=True)
    ~~~~~~~~~~~~^^^^^^^^^^^^^^^
  File "<string>", line 2, in commit
  File "D:\MVP_FullStack_Backend\env\Lib\site-packages\sqlalchemy\orm\state_changes.py", line 139, in _go
    ret_value = fn(self, *arg, **kw)
  File "D:\MVP_FullStack_Backend\env\Lib\site-packages\sqlalchemy\orm\session.py", line 1313, in commit
    self._prepare_impl()
    ~~~~~~~~~~~~~~~~~~^^
  File "<string>", line 2, in _prepare_impl
  File "D:\MVP_FullStack_Backend\env\Lib\site-packages\sqlalchemy\orm\state_changes.py", line 139, in _go
    ret_value = fn(self, *arg, **kw)
  File "D:\MVP_FullStack_Backend\env\Lib\site-packages\sqlalchemy\orm\session.py", line 1288, in _prepare_impl
    self.session.flush()
    ~~~~~~~~~~~~~~~~~~^^
  File "D:\MVP_FullStack_Backend\env\Lib\site-packages\sqlalchemy\orm\session.py", line 4352, in flush
    self._flush(objects)
    ~~~~~~~~~~~^^^^^^^^^
  File "D:\MVP_FullStack_Backend\env\Lib\site-packages\sqlalchemy\orm\session.py", line 4487, in _flush
    with util.safe_reraise():
         ~~~~~~~~~~~~~~~~~^^
  File "D:\MVP_FullStack_Backend\env\Lib\site-packages\sqlalchemy\util\langhelpers.py", line 146, in __exit__
    raise exc_value.with_traceback(exc_tb)
  File "D:\MVP_FullStack_Backend\env\Lib\site-packages\sqlalchemy\orm\session.py", line 4448, in _flush
    flush_context.execute()
    ~~~~~~~~~~~~~~~~~~~~~^^
  File "D:\MVP_FullStack_Backend\env\Lib\site-packages\sqlalchemy\orm\unitofwork.py", line 466, in execute
    rec.execute(self)
    ~~~~~~~~~~~^^^^^^
  File "D:\MVP_FullStack_Backend\env\Lib\site-packages\sqlalchemy\orm\unitofwork.py", line 642, in execute
    util.preloaded.orm_persistence.save_obj(
    ~~~~~~~~~~~~~~~~~~~~~~~~~~~~~~~~~~~~~~~^
        self.mapper,
        ^^^^^^^^^^^^
        uow.states_for_mapper_hierarchy(self.mapper, False, False),
        ^^^^^^^^^^^^^^^^^^^^^^^^^^^^^^^^^^^^^^^^^^^^^^^^^^^^^^^^^^^
        uow,
        ^^^^
    )
    ^
  File "D:\MVP_FullStack_Backend\env\Lib\site-packages\sqlalchemy\orm\persistence.py", line 93, in save_obj
    _emit_insert_statements(
    ~~~~~~~~~~~~~~~~~~~~~~~^
        base_mapper,
        ^^^^^^^^^^^^
    ...<3 lines>...
        insert,
        ^^^^^^^
    )
    ^
  File "D:\MVP_FullStack_Backend\env\Lib\site-packages\sqlalchemy\orm\persistence.py", line 1048, in _emit_insert_statements
    result = connection.execute(
        statement, multiparams, execution_options=execution_options
    )
  File "D:\MVP_FullStack_Backend\env\Lib\site-packages\sqlalchemy\engine\base.py", line 1418, in execute
    return meth(
        self,
        distilled_parameters,
        execution_options or NO_OPTIONS,
    )
  File "D:\MVP_FullStack_Backend\env\Lib\site-packages\sqlalchemy\sql\elements.py", line 515, in _execute_on_connection
    return connection._execute_clauseelement(
           ~~~~~~~~~~~~~~~~~~~~~~~~~~~~~~~~~^
        self, distilled_params, execution_options
        ^^^^^^^^^^^^^^^^^^^^^^^^^^^^^^^^^^^^^^^^^
    )
    ^
  File "D:\MVP_FullStack_Backend\env\Lib\site-packages\sqlalchemy\engine\base.py", line 1640, in _execute_clauseelement
    ret = self._execute_context(
        dialect,
    ...<8 lines>...
        cache_hit=cache_hit,
    )
  File "D:\MVP_FullStack_Backend\env\Lib\site-packages\sqlalchemy\engine\base.py", line 1846, in _execute_context
    return self._exec_single_context(
           ~~~~~~~~~~~~~~~~~~~~~~~~~^
        dialect, context, statement, parameters
        ^^^^^^^^^^^^^^^^^^^^^^^^^^^^^^^^^^^^^^^
    )
    ^
  File "D:\MVP_FullStack_Backend\env\Lib\site-packages\sqlalchemy\engine\base.py", line 1986, in _exec_single_context
    self._handle_dbapi_exception(
    ~~~~~~~~~~~~~~~~~~~~~~~~~~~~^
        e, str_statement, effective_parameters, cursor, context
        ^^^^^^^^^^^^^^^^^^^^^^^^^^^^^^^^^^^^^^^^^^^^^^^^^^^^^^^
    )
    ^
  File "D:\MVP_FullStack_Backend\env\Lib\site-packages\sqlalchemy\engine\base.py", line 2355, in _handle_dbapi_exception
    raise sqlalchemy_exception.with_traceback(exc_info[2]) from e
  File "D:\MVP_FullStack_Backend\env\Lib\site-packages\sqlalchemy\engine\base.py", line 1967, in _exec_single_context
    self.dialect.do_execute(
    ~~~~~~~~~~~~~~~~~~~~~~~^
        cursor, str_statement, effective_parameters, context
        ^^^^^^^^^^^^^^^^^^^^^^^^^^^^^^^^^^^^^^^^^^^^^^^^^^^^
    )
    ^
  File "D:\MVP_FullStack_Backend\env\Lib\site-packages\sqlalchemy\engine\default.py", line 941, in do_execute
    cursor.execute(statement, parameters)
    ~~~~~~~~~~~~~~^^^^^^^^^^^^^^^^^^^^^^^
sqlalchemy.exc.IntegrityError: (sqlite3.IntegrityError) UNIQUE constraint failed: banco.idBanco
[SQL: INSERT INTO banco ("idBanco", descricao) VALUES (?, ?)]
[parameters: (63, 'BANCO BRADESCARD S.A.')]
(Background on this error at: https://sqlalche.me/e/20/gkpj)

During handling of the above exception, another exception occurred:

Traceback (most recent call last):
  File "D:\MVP_FullStack_Backend\env\Lib\site-packages\flask\app.py", line 1473, in wsgi_app
    response = self.full_dispatch_request()
  File "D:\MVP_FullStack_Backend\env\Lib\site-packages\flask\app.py", line 882, in full_dispatch_request
    rv = self.handle_user_exception(e)
  File "D:\MVP_FullStack_Backend\env\Lib\site-packages\flask_cors\extension.py", line 194, in wrapped_function
    return cors_after_request(app.make_response(f(*args, **kwargs)))
                                                ~^^^^^^^^^^^^^^^^^
  File "D:\MVP_FullStack_Backend\env\Lib\site-packages\flask\app.py", line 880, in full_dispatch_request
    rv = self.dispatch_request()
  File "D:\MVP_FullStack_Backend\env\Lib\site-packages\flask\app.py", line 865, in dispatch_request
    return self.ensure_sync(self.view_functions[rule.endpoint])(**view_args)  # type: ignore[no-any-return]
           ~~~~~~~~~~~~~~~~~~~~~~~~~~~~~~~~~~~~~~~~~~~~~~~~~~~~^^^^^^^^^^^^^
  File "D:\MVP_FullStack_Backend\env\Lib\site-packages\flask_openapi3\scaffold.py", line 117, in view_func
    response = func(**func_kwargs)
  File "D:\MVP_FullStack_Backend\app.py", line 256, in add_banco
    logger.warning(f"Erro ao adicionar nova Instiuição Financeira '{banco.idBanco}', {error_msg}")
                                                                                      ^^^^^^^^^
UnboundLocalError: cannot access local variable 'error_msg' where it is not associated with a value
